Workbook

Sheet Development Databook
A1: DATA AS OF | B1: DEVELOPMENT | C1: HUD AMP# | D1: TDS# | E1: CONSOLIDATED TDS# | F1: DEVELOPMENT EDP# | G1: OPERATING EDP# | H1: HUD # | I1: PROGRAM | J1: METHOD | K1: TYPE | L1: NUMBER OF SECTION 8 TRANSITION APARTMENTS | M1: NUMBER OF CURRENT APARTMENTS | N1: TOTAL NUMBER OF APARTMENTS | O1: NUMBER OF RENTAL ROOMS | P1: AVG NO R/R PER APARTMENT | Q1: POPULATION SECTION 8 TRANSITION | R1: POPULATION PUBLIC HOUSING | S1: TOTAL POPULATION | T1: TOTAL # OF FIXED INCOME HOUSEHOLD | U1: PERCENT FIXED INCOME HOUSEHOLDS | V1: NUMBER OF RESIDENTIAL BLDGS | W1: NUMBER OF NON-RESIDENTIAL BLDGS | X1: NUMBER OF STAIRHALLS | Y1: NUMBER OF STORIES | Z1: TOTAL AREA SQ FT | AA1: ACRES | AB1: NET DEV AREA SQ FT | AC1: EXCLUDING PARK ACRES | AD1: BLDG COVERAGE SQ FT | AE1: CUBAGE CU FT | AF1: BLDG COVERAGE % | AG1: DENSITY | AH1: DEVELOPMENT COST | AI1: PER RENTAL ROOM | AJ1: AVG MONTHLY GROSS RENT | AK1: LOCATION STREET A | AL1: LOCATION STREET B | AM1: LOCATION STREET C | AN1: LOCATION STREET D | AO1: BOROUGH | AP1: COMMUNITY DISTIRCT | AQ1: US CONGRESSIONAL DISTRICT | AR1: NY STATE SENATE DISTRICT | AS1: NY STATE ASSEMBLY DISTRICT | AT1: NY CITY COUNCIL DISTRICT | AU1: COMPLETION DATE | AV1: FEDERALIZED DEVELOPMENT | AW1: SENIOR DEVELOPMENT | AX1: ELECTRICITY PAID BY RESIDENTS | AY1: PRIVATE MANAGEMENT
A2: 43466 | B2: 1010 EAST 178TH STREET | C2: NY005011330 | D2: 180 | E2: 180 | F2: 289 | G2: 289 | H2: NY005090 | I2: FEDERAL | J2: CONVENTIONAL | K2: NEW CONST | M2: 218 | N2: 220 | O2: 918 | P2: 4.21 | R2: 450 | S2: 450 | T2: 89 | U2: 0.418 | V2: 1 | W2: 0 | X2: 1 | Y2: 21 | Z2: 88172 | AA2: 2.02 | AB2: 88172 | AC2: 2.02 | AD2: 14961 | AE2: 1841787 | AF2: 0.1697 | AG2: 223 | AH2: 5031405 | AI2: 5341 | AJ2: 503 | AK2: E TREMONT AVE | AL2: BRYANT AVE | AM2: E 178TH ST | AN2: BOSTON RD | AO2: BRONX | AP2: 6 | AQ2: 15 | AR2: 32 | AS2: 87 | AT2: 15 | AU2: 26023
A3: 43466 | B3: 104-14 TAPSCOTT STREET | C3: NY005011670 | D3: 242 | E3: 167 | F3: 361 | G3: 283 | H3: NY005174 | I3: FEDERAL | J3: TURNKEY | K3: NEW CONST | M3: 30 | N3: 30 | O3: 131 | P3: 4.37 | R3: 65 | S3: 65 | T3: 5 | U3: 0.172 | V3: 1 | W3: 0 | X3: 1 | Y3: 4 | Z3: 10000 | AA3: 0.23 | AB3: 10000 | AC3: 0.23 | AD3: 6983 | AE3: 351238 | AF3: 0.6983 | AG3: 283 | AH3: 839110 | AI3: 6505 | AJ3: 643 | AK3: TAPSCOTT ST | AL3: UNION ST | AM3: SUTTER AVE | AN3: BLAKE AVE | AO3: BROOKLYN | AP3: 16 | AQ3: 9 | AR3: 20 | AS3: 55 | AT3: 41 | AU3: 26603
A4: 43466 | B4: 1162-1176 WASHINGTON AVENUE | C4: NY005013080 | D4: 233 | E4: 308 | F4: 354 | G4: 344 | H4: NY005138 | I4: FEDERAL | J4: TURNKEY | K4: REHAB | M4: 65 | N4: 66 | O4: 293.5 | P4: 4.52 | R4: 170 | S4: 170 | T4: 21 | U4: 0.328 | V4: 1 | W4: 0 | X4: 1 | Y4: 6 | Z4: 18987 | AA4: 0.44 | AB4: 18987 | AC4: 0.44 | AD4: 12231 | AE4: 851926 | AF4: 0.6442 | AG4: 386 | AH4: 2205187 | AI4: 7302 | AJ4: 440 | AK4: E 167TH ST | AL4: E 168TH ST | AM4: THIRD AVE | AN4: WASHINGTON AVE | AO4: BRONX | AP4: 3 | AQ4: 15 | AR4: 32 | AS4: 79 | AT4: 16 | AU4: 27759
A5: 43466 | B5: 131 SAINT NICHOLAS AVENUE | C5: NY005010970 | D5: 154 | E5: 97 | F5: 264 | G5: 261 | H5: NY005065 | I5: FEDERAL | J5: CONVENTIONAL | K5: NEW CONST | M5: 98 | N5: 100 | O5: 386 | P5: 3.94 | R5: 165 | S5: 165 | T5: 41 | U5: 0.427 | V5: 1 | W5: 0 | X5: 1 | Y5: 17 | Z5: 29359 | AA5: 0.67 | AB5: 29359 | AC5: 0.67 | AD5: 5759 | AE5: 771591 | AF5: 0.1962 | AG5: 246 | AH5: 1880013 | AI5: 4694 | AJ5: 529 | AK5: SAINT NICHOLAS AVE | AL5: W 116TH ST | AM5: W 117TH ST | AO5: MANHATTAN | AP5: 10 | AQ5: 13 | AR5: 30 | AS5: 70 | AT5: 9 | AU5: 23832
A6: 43466 | B6: 1471 WATSON AVENUE | C6: NY005010670 | D6: 214 | E6: 67 | F6: 332 | G6: 222 | H6: NY005162 | I6: FEDERAL | J6: TURNKEY | K6: NEW CONST | M6: 96 | N6: 96 | O6: 386 | P6: 4.02 | R6: 156 | S6: 156 | T6: 47 | U6: 0.505 | V6: 1 | W6: 0 | X6: 1 | Y6: 6 | Z6: 39937 | AA6: 0.92 | AB6: 39937 | AC6: 0.92 | AD6: 13337 | AE6: 810629 | AF6: 0.334 | AG6: 170 | AH6: 2278928 | AI6: 5814 | AJ6: 452 | AK6: WATSON AVE | AL6: COLGATE AVE | AM6: EVERGREEN AVE | AO6: BRONX | AP6: 9 | AQ6: 15 | AR6: 32 | AS6: 85 | AT6: 17 | AU6: 25933
A7: 43466 | B7: 154 WEST 84TH STREET | C7: NY005013590 | D7: 359 | E7: 359 | F7: 840 | G7: 840 | H7: NY005270 | I7: FEDERAL | J7: TURNKEY | K7: NEW CONST | M7: 35 | N7: 35 | O7: 157.5 | P7: 4.5 | R7: 74 | S7: 74 | T7: 7 | U7: 0.2 | V7: 1 | W7: 0 | X7: 1 | Y7: 7 | Z7: 9621 | AA7: 0.22 | AB7: 9621 | AC7: 0.22 | AD7: 5774 | AE7: 361857 | AF7: 0.6001 | AG7: 336 | AH7: 4503296 | AI7: 28412 | AJ7: 644 | AK7: AMSTERDAM AVE | AL7: W 84TH ST | AM7: COLUMBUS AVE | AO7: MANHATTAN | AP7: 7 | AQ7: 10 | AR7: 29 | AS7: 69 | AT7: 6 | AU7: 35155 | AX7: YES | AY7: YES
A8: 43466 | B8: 303 VERNON AVENUE | C8: NY005010730 | D8: 156 | E8: 73 | F8: 267 | G8: 267 | H8: NY005068 | I8: FEDERAL | J8: CONVENTIONAL | K8: NEW CONST | M8: 234 | N8: 234 | O8: 1101 | P8: 4.71 | R8: 541 | S8: 541 | T8: 100 | U8: 0.431 | V8: 1 | W8: 0 | X8: 1 | Y8: 24 | Z8: 110000 | AA8: 2.53 | AB8: 110000 | AC8: 2.53 | AD8: 11311 | AE8: 2207369 | AF8: 0.1028 | AG8: 214 | AH8: 4703702 | AI8: 4272 | AJ8: 511 | AK8: VERNON AVE | AL8: MARCUS GARVEY BLVD | AM8: MYRTLE AVE | AO8: BROOKLYN | AP8: 3 | AQ8: 8 | AR8: 18 | AS8: 54 | AT8: 36 | AU8: 24623
A9: 43466 | B9: 335 EAST 111TH STREET | C9: NY005010640 | D9: 203 | E9: 64 | F9: 320 | G9: 219 | H9: NY005126 | I9: FEDERAL | J9: TURNKEY | K9: NEW CONST | M9: 66 | N9: 66 | O9: 259 | P9: 3.92 | R9: 114 | S9: 114 | T9: 33 | U9: 0.5 | V9: 1 | W9: 0 | X9: 1 | Y9: 6 | Z9: 20205 | AA9: 0.46 | AB9: 20205 | AC9: 0.46 | AD9: 9143 | AE9: 530550 | AF9: 0.4525 | AG9: 248 | AH9: 1241825 | AI9: 4651 | AJ9: 482 | AK9: SECOND AVE | AL9: E 111TH ST | AM9: FIRST AVE | AN9: E 112TH ST | AO9: MANHATTAN | AP9: 11 | AQ9: 13 | AR9: 29 | AS9: 68 | AT9: 8 | AU9: 25384
A10: 43466 | B10: 344 EAST 28TH STREET | C10: NY005021850 | D10: 185 | E10: 153 | F10: 452 | G10: 452 | H10: NY005374 | I10: MIXED FINANCE/LLC2 | J10: CONVENTIONAL | K10: NEW CONST | L10: 73 | M10: 225 | N10: 225 | O10: 985.5 | P10: 4.38 | Q10: 146 | R10: 281 | S10: 427 | T10: 111 | U10: 0.502 | V10: 1 | W10: 0 | X10: 1 | Y10: 26 | Z10: 44644 | AA10: 1.02 | AB10: 44644 | AC10: 1.02 | AD10: 7889 | AE10: 1946457 | AF10: 0.1767 | AG10: 419 | AH10: 4980000 | AI10: 5053 | AJ10: 516 | AK10: E 27TH ST | AL10: NEW ST | AM10: E 28TH ST | AN10: FIRST AVE | AO10: MANHATTAN | AP10: 6 | AQ10: 12 | AR10: 27 | AS10: 74 | AT10: 2 | AU10: 26023
A11: 43466 | B11: 45 ALLEN STREET | C11: NY005011000 | D11: 265 | E11: 100 | F11: 380 | G11: 312 | H11: NY005186 | I11: FEDERAL | J11: TURNKEY | K11: NEW CONST | M11: 107 | N11: 107 | O11: 537.5 | P11: 5.02 | R11: 237 | S11: 237 | T11: 46 | U11: 0.442 | V11: 1 | W11: 1 | X11: 2 | Y11: 14 | Z11: 39609 | AA11: 0.91 | AB11: 39609 | AC11: 0.91 | AD11: 8031 | AE11: 950162 | AF11: 0.2028 | AG11: 260 | AH11: 4290021 | AI11: 7981 | AJ11: 687 | AK11: GRAND ST | AL11: ALLEN ST | AM11: HESTER ST | AN11: ELDRIDGE ST | AO11: MANHATTAN | AP11: 3 | AQ11: 7 | AR11: 26 | AS11: 65 | AT11: 1 | AU11: 27241
A12: 43466 | B12: 572 WARREN STREET | C12: NY005011630 | D12: 196 | E12: 163 | F12: 307 | G12: 272 | H12: NY005103 | I12: FEDERAL | J12: TURNKEY | K12: NEW CONST | M12: 200 | N12: 200 | O12: 815 | P12: 4.08 | R12: 375 | S12: 375 | T12: 84 | U12: 0.42 | V12: 1 | W12: 1 | X12: 2 | Y12: 6 | Z12: 81700 | AA12: 1.88 | AB12: 81700 | AC12: 1.88 | AD12: 28530 | AE12: 1726301 | AF12: 0.3492 | AG12: 199 | AH12: 5984598 | AI12: 7116 | AJ12: 536 | AK12: WARREN ST | AL12: BALTIC ST | AM12: THIRD AVE | AN12: FOURTH AVE | AO12: BROOKLYN | AP12: 6 | AQ12: 7 | AR12: 25 | AS12: 52 | AT12: 33 | AU12: 26542
A13: 43466 | B13: 830 AMSTERDAM AVENUE | C13: NY005010820 | D13: 150 | E13: 82 | F13: 258 | G13: 258 | H13: NY005059 | I13: FEDERAL | J13: CONVENTIONAL | K13: NEW CONST | M13: 158 | N13: 159 | O13: 724 | P13: 4.58 | R13: 351 | S13: 351 | T13: 63 | U13: 0.404 | V13: 1 | W13: 0 | X13: 1 | Y13: 20 | Z13: 28690 | AA13: 0.66 | AB13: 28690 | AC13: 0.66 | AD13: 7750 | AE13: 1375740 | AF13: 0.2701 | AG13: 532 | AH13: 3631814 | AI13: 4992 | AJ13: 492 | AK13: W 101ST ST | AL13: AMSTERDAM AVE | AM13: W 100TH ST | AO13: MANHATTAN | AP13: 7 | AQ13: 10 | AR13: 30 | AS13: 69 | AT13: 7 | AU13: 23985
A14: 43466 | B14: ADAMS | C14: NY005001180 | D14: 118 | E14: 118 | F14: 248 | G14: 248 | H14: NY005049 | I14: FEDERAL | J14: CONVENTIONAL | K14: NEW CONST | M14: 924 | N14: 925 | O14: 4306 | P14: 4.66 | R14: 2310 | S14: 2310 | T14: 335 | U14: 0.364 | V14: 7 | W14: 0 | X14: 7 | Y14: 15-21 | Z14: 408888 | AA14: 9.39 | AB14: 383068 | AC14: 8.79 | AD14: 56283 | AE14: 8181502 | AF14: 0.1376 | AG14: 246 | AH14: 17878818 | AI14: 4149 | AJ14: 497 | AK14: WESTCHESTER AVE | AL14: UNION AVE | AM14: E 152ND ST | AO14: BRONX | AP14: 1 | AQ14: 15 | AR14: 29 | AS14: 84 | AT14: 17 | AU14: 23620
A15: 43466 | B15: ALBANY | C15: NY005010310 | D15: 31 | E15: 31 | F15: 524 | G15: 524 | H15: NY005216C | I15: FEDERAL | J15: CONVENTIONAL | K15: NEW CONST | M15: 823 | N15: 829 | O15: 3777.5 | P15: 4.59 | R15: 1886 | S15: 1886 | T15: 267 | U15: 0.327 | V15: 6 | W15: 0 | X15: 6 | Y15: 14 | Z15: 388389 | AA15: 8.92 | AB15: 388389 | AC15: 8.92 | AD15: 58455 | AE15: 7082630 | AF15: 0.1505 | AG15: 211 | AH15: 8951000 | AI15: 2356 | AJ15: 565 | AK15: ALBANY AVE | AL15: SAINT MARKS AVE | AM15: TROY AVE | AN15: PARK PL | AO15: BROOKLYN | AP15: 8 | AQ15: 9 | AR15: 25 | AS15: 56 | AT15: 36 | AU15: 18550 | AV15: 1978/02/01-ATP 2
A16: 43466 | B16: ALBANY II | C16: NY005010310 | D16: 85 | E16: 31 | F16: 524 | G16: 524 | H16: NY005216C | I16: FEDERAL | J16: CONVENTIONAL | K16: NEW CONST | M16: 400 | N16: 400 | O16: 1848 | P16: 4.62 | R16: 985 | S16: 985 | T16: 130 | U16: 0.331 | V16: 3 | W16: 0 | X16: 3 | Y16: 13-14 | Z16: 214594 | AA16: 4.93 | AB16: 214594 | AC16: 4.93 | AD16: 26053 | AE16: 3249689 | AF16: 0.1214 | AG16: 200 | AH16: 4666000 | AI16: 2540 | AJ16: 542 | AK16: BERGEN ST | AL16: TROY AVE | AM16: ALBANY HOUSES | AN16: ALBANY AVE | AO16: BROOKLYN | AP16: 8 | AQ16: 9 | AR16: 25 | AS16: 56 | AT16: 36 | AU16: 20858 | AV16: 1978/02/01-ATP 2
A17: 43466 | B17: AMSTERDAM | C17: NY005010220 | D17: 22 | E17: 22 | F17: 530 | G17: 530 | H17: NY005220A | I17: FEDERAL | J17: CONVENTIONAL | K17: NEW CONST | M17: 1084 | N17: 1084 | O17: 5129 | P17: 4.73 | R17: 2270 | S17: 2270 | T17: 468 | U17: 0.435 | V17: 13 | W17: 0 | X17: 24 | Y17: 43629 | Z17: 446172 | AA17: 10.24 | AB17: 413534 | AC17: 9.49 | AD17: 100358 | AE17: 8233310 | AF17: 0.2249 | AG17: 222 | AH17: 12262000 | AI17: 2391 | AJ17: 544 | AK17: W 61ST ST | AL17: W 64TH ST | AM17: WEST END AVE | AN17: AMSTERDAM AVE | AO17: MANHATTAN | AP17: 7 | AQ17: 10 | AR17: 31 | AS17: 67 | AT17: 6 | AU17: 17884 | AV17: 1978/07/01-ATP 3
A18: 43466 | B18: AMSTERDAM ADDITION | C18: NY005021870 | D18: 187 | E18: 22 | F18: 453 | G18: 453 | H18: NY005366 | I18: MIXED FINANCE/LLC1 | J18: CONVENTIONAL | K18: NEW CONST | L18: 26 | M18: 175 | N18: 175 | O18: 762.5 | P18: 4.36 | Q18: 66 | R18: 287 | S18: 353 | T18: 97 | U18: 0.557 | V18: 1 | W18: 0 | X18: 1 | Y18: 27 | Z18: 36154 | AA18: 0.83 | AB18: 36154 | AC18: 0.83 | AD18: 17562 | AE18: 1825587 | AF18: 0.4858 | AG18: 425 | AH18: 7053000 | AI18: 9250 | AJ18: 510 | AK18: W 64TH ST | AL18: W 65TH ST | AM18: AMSTERDAM AVE | AN18: WEST END AVE | AO18: MANHATTAN | AP18: 7 | AQ18: 10 | AR18: 31 | AS18: 67 | AT18: 6 | AU18: 27060
A19: 43466 | B19: ARMSTRONG I | C19: NY005012100 | D19: 210 | E19: 210 | F19: 325 | G19: 325 | H19: NY005120 | I19: FEDERAL | J19: CONVENTIONAL | K19: NEW CONST | M19: 369 | N19: 371 | O19: 1763.5 | P19: 4.78 | R19: 977 | S19: 977 | T19: 143 | U19: 0.39 | V19: 11 | W19: 1 | X19: 58 | Y19: 38780 | Z19: 245481 | AA19: 5.64 | AB19: 245481 | AC19: 5.64 | AD19: 94311 | AE19: 4800020 | AF19: 0.3842 | AG19: 173 | AH19: 14648872 | AI19: 8129 | AJ19: 581 | AK19: CLIFTON PL | AL19: MARCY AVE | AM19: GATES AVE | AN19: BEDFORD AVE | AO19: BROOKLYN | AP19: 3 | AQ19: 8 | AR19: 25 | AS19: 56, 57 | AT19: 36 | AU19: 26815 | AW19: PARTIALLY
A20: 43466 | B20: ARMSTRONG II | C20: NY005012100 | D20: 228 | E20: 210 | F20: 355 | G20: 325 | H20: NY005116 | I20: FEDERAL | J20: TURNKEY | K20: NEW CONST | M20: 248 | N20: 248 | O20: 1276 | P20: 5.15 | R20: 702 | S20: 702 | T20: 58 | U20: 0.238 | V20: 5 | W20: 1 | X20: 17 | Y20: 4 | Z20: 162118 | AA20: 3.72 | AB20: 162118 | AC20: 3.72 | AD20: 67372 | AE20: 3123424 | AF20: 0.4156 | AG20: 189 | AH20: 7802067 | AI20: 6114 | AJ20: 600 | AK20: GREENE AVE | AL20: GATES AVE | AM20: TOMPKINS AVE | AN20: MARCY AVE | AO20: BROOKLYN | AP20: 3 | AQ20: 8 | AR20: 25 | AS20: 56 | AT20: 36 | AU20: 27333
A21: 43466 | B21: ASTORIA | C21: NY005000260 | D21: 26 | E21: 26 | F21: 517 | G21: 517 | H21: NY005213I | I21: FEDERAL | J21: CONVENTIONAL | K21: NEW CONST | M21: 1104 | N21: 1104 | O21: 5607 | P21: 5.08 | R21: 3032 | S21: 3032 | T21: 366 | U21: 0.333 | V21: 22 | W21: 1 | X21: 22 | Y21: 43623 | Z21: 1406832 | AA21: 32.3 | AB21: 1151484 | AC21: 26.43 | AD21: 173434 | AE21: 10826559 | AF21: 0.1233 | AG21: 94 | AH21: 14122000 | AI21: 2519 | AJ21: 593 | AK21: 27TH AVE | AL21: 8TH ST | AM21: HALLET'S COVE | AN21: EAST RIVER | AO21: QUEENS | AP21: 1 | AQ21: 12 | AR21: 12 | AS21: 37 | AT21: 22 | AU21: 18941 | AV21: 1977/07/01-ATP 1
A22: 43466 | B22: ATLANTIC TERMINAL SITE 4B | C22: NY005011630 | D22: 256 | E22: 163 | F22: 384 | G22: 272 | H22: NY005189 | I22: FEDERAL | J22: TURNKEY | K22: NEW CONST | M22: 299 | N22: 300 | O22: 1237.5 | P22: 4.14 | R22: 582 | S22: 582 | T22: 121 | U22: 0.41 | V22: 1 | W22: 0 | X22: 1 | Y22: 31 | Z22: 88155 | AA22: 2.02 | AB22: 88155 | AC22: 2.02 | AD22: 15382 | AE22: 2464800 | AF22: 0.1745 | AG22: 288 | AH22: 10797972 | AI22: 8489 | AJ22: 562 | AK22: CLERMONT AVE | AL22: ATLANTIC AVE | AM22: CARLTON AVE | AN22: FULTON ST | AO22: BROOKLYN | AP22: 2 | AQ22: 8 | AR22: 25 | AS22: 57 | AT22: 35 | AU22: 27880
A23: 43466 | B23: AUDUBON | C23: NY005010030 | D23: 125 | E23: 3 | F23: 444 | G23: 444 | H23: NY005365 | I23: FEDERAL | J23: CONVENTIONAL | K23: NEW CONST | M23: 167 | N23: 168 | O23: 826.5 | P23: 4.95 | R23: 446 | S23: 446 | T23: 64 | U23: 0.388 | V23: 1 | W23: 0 | X23: 1 | Y23: 20 | Z23: 27477 | AA23: 0.63 | AB23: 27477 | AC23: 0.63 | AD23: 9043 | AE23: 1585892 | AF23: 0.3291 | AG23: 708 | AH23: 2817000 | AI23: 3382 | AJ23: 578 | AK23: W 154TH ST | AL23: W 155TH ST | AM23: AMSTERDAM AVE | AO23: MANHATTAN | AP23: 9 | AQ23: 13 | AR23: 30 | AS23: 71 | AT23: 7 | AU23: 22766 | AV23: 1995/07/13-PTA
A24: 43466 | B24: BAILEY AVENUE-WEST 193RD STREET | C24: NY005012020 | D24: 202 | E24: 197 | F24: 311 | G24: 311 | H24: NY005106 | I24: FEDERAL | J24: CONVENTIONAL | K24: NEW CONST | M24: 232 | N24: 233 | O24: 976 | P24: 4.21 | R24: 455 | S24: 455 | T24: 89 | U24: 0.387 | V24: 1 | W24: 0 | X24: 1 | Y24: 20 | Z24: 99606 | AA24: 2.29 | AB24: 99606 | AC24: 2.29 | AD24: 13621 | AE24: 1877893 | AF24: 0.1367 | AG24: 199 | AH24: 8091156 | AI24: 8173 | AJ24: 493 | AK24: BAILEY AVE | AL24: W 193RD ST | AM24: HEATH AVE | AO24: BRONX | AP24: 7 | AQ24: 13 | AR24: 33 | AS24: 86 | AT24: 14 | AU24: 26815
A25: 43466 | B25: BAISLEY PARK | C25: NY005010910 | D25: 91 | E25: 91 | F25: 240 | G25: 240 | H25: NY005038 | I25: FEDERAL | J25: CONVENTIONAL | K25: NEW CONST | M25: 381 | N25: 386 | O25: 1779.5 | P25: 4.67 | R25: 947 | S25: 947 | T25: 143 | U25: 0.377 | V25: 5 | W25: 1 | X25: 8 | Y25: 8 | Z25: 325713 | AA25: 7.48 | AB25: 325713 | AC25: 7.48 | AD25: 54504 | AE25: 3529560 | AF25: 0.1673 | AG25: 127 | AH25: 5856304 | AI25: 3246 | AJ25: 548 | AK25: LIRR | AL25: FOCH BLVD | AM25: 116TH AVE | AN25: GUY BREWER BLVD | AO25: QUEENS | AP25: 12 | AQ25: 5 | AR25: 10, 14 | AS25: 32 | AT25: 28 | AU25: 22401
A26: 43466 | B26: BARUCH | C26: NY005010600 | D26: 60 | E26: 60 | F26: 215 | G26: 215 | H26: NY005012 | I26: FEDERAL | J26: CONVENTIONAL | K26: NEW CONST | M26: 2193 | N26: 2194 | O26: 10240.5 | P26: 4.67 | R26: 4872 | S26: 4872 | T26: 962 | U26: 0.445 | V26: 17 | W26: 1 | X26: 35 | Y26: 41833 | Z26: 1196115 | AA26: 27.46 | AB26: 1101503 | AC26: 25.29 | AD26: 160098 | AE26: 17784205 | AF26: 0.1338 | AG26: 177 | AH26: 36411155 | AI26: 3553 | AJ26: 534 | AK26: E HOUSTON ST | AL26: FDR DRIVE | AM26: DELANCEY ST | AN26: COLUMBIA ST | AO26: MANHATTAN | AP26: 3 | AQ26: 7 | AR26: 26 | AS26: 74 | AT26: 2 | AU26: 21768
A27: 43466 | B27: BARUCH HOUSES ADDITION | C27: NY005010600 | D27: 198 | E27: 60 | F27: 383 | G27: 215 | H27: NY005111 | I27: FEDERAL | J27: CONVENTIONAL | K27: NEW CONST (ELD) | M27: 197 | N27: 197 | O27: 646.5 | P27: 3.28 | R27: 242 | S27: 242 | T27: 179 | U27: 0.923 | V27: 1 | W27: 0 | X27: 1 | Y27: 23 | Z27: 47204 | AA27: 1.08 | AB27: 47204 | AC27: 1.08 | AD27: 6149 | AE27: 1268931 | AF27: 0.1303 | AG27: 224 | AH27: 6622549 | AI27: 9907 | AJ27: 302 | AK27: COLUMBIA ST | AL27: DELANCEY ST | AM27: E HOUSTON ST | AN27: FDR DRIVE | AO27: MANHATTAN | AP27: 3 | AQ27: 7 | AR27: 26 | AS27: 74 | AT27: 2 | AU27: 28245 | AW27: EXCLUSIVELY
A28: 43466 | B28: BAY VIEW | C28: NY005020920 | D28: 92 | E28: 92 | F28: 670 | G28: 670 | H28: NY005368 | I28: MIXED FINANCE/LLC1 | J28: CONVENTIONAL | K28: NEW CONST | L28: 340 | M28: 1609 | N28: 1610 | O28: 7310.5 | P28: 4.54 | Q28: 871 | R28: 2635 | S28: 3506 | T28: 620 | U28: 0.388 | V28: 23 | W28: 2 | X28: 26 | Y28: 8 | Z28: 1481844 | AA28: 34.02 | AB28: 1459244 | AC28: 33.5 | AD28: 228305 | AE28: 14262296 | AF28: 0.1541 | AG28: 103 | AH28: 19575470 | AI28: 2676 | AJ28: 529 | AK28: SEAVIEW AVE | AL28: E 102ND ST | AM28: ROCKAWAY PKWY | AN28: SHORE PKWY | AO28: BROOKLYN | AP28: 18 | AQ28: 8 | AR28: 19 | AS28: 59 | AT28: 46 | AU28: 20613
A29: 43466 | B29: BEACH 41ST STREET-BEACH CHANNEL DRIVE | C29: NY005001650 | D29: 165 | E29: 165 | F29: 282 | G29: 282 | H29: NY005086 | I29: FEDERAL | J29: CONVENTIONAL | K29: NEW CONST | M29: 712 | N29: 712 | O29: 3106 | P29: 4.36 | R29: 1622 | S29: 1622 | T29: 233 | U29: 0.335 | V29: 4 | W29: 1 | X29: 7 | Y29: 13 | Z29: 580000 | AA29: 13.31 | AB29: 580000 | AC29: 13.31 | AD29: 66756 | AE29: 6385727 | AF29: 0.1151 | AG29: 122 | AH29: 24811000 | AI29: 7988 | AJ29: 470 | AK29: B 38TH ST | AL29: B 41ST ST | AM29: NORTON AVE | AN29: B CHANNEL DR | AO29: QUEENS | AP29: 14 | AQ29: 5 | AR29: 10 | AS29: 31 | AT29: 31 | AU29: 26998
A30: 43466 | B30: BEDFORD-STUYVESANT REHAB | C30: NY005010730 | D30: 311 | E30: 73 | F30: 266 | G30: 538 | H30: NY005255 | I30: FEDERAL | J30: TURNKEY | K30: REHAB | M30: 84 | N30: 85 | O30: 381 | P30: 4.54 | R30: 180 | S30: 180 | T30: 29 | U30: 0.349 | V30: 3 | W30: 0 | X30: 5 | Y30: 43561 | Z30: 26000 | AA30: 0.6 | AB30: 26000 | AC30: 0.6 | AD30: 18283 | AE30: 856611 | AF30: 0.7032 | AG30: 300 | AH30: 5219763 | AI30: 13316 | AJ30: 579 | AK30: THROOP AVE | AL30: VERNON AVE | AM30: MARCUS GARVEY BLVD | AN30: HART ST | AO30: BROOKLYN | AP30: 3 | AQ30: 8 | AR30: 18 | AS30: 54 | AT30: 36 | AU30: 30467 | AX30: YES
A31: 43466 | B31: BELMONT-SUTTER AREA | C31: NY005010460 | D31: 345 | E31: 46 | F31: 761 | G31: 761 | H31: NY005282 | I31: FEDERAL | J31: TURNKEY | K31: NEW CONST | M31: 72 | N31: 72 | O31: 336 | P31: 4.67 | R31: 189 | S31: 189 | T31: 21 | U31: 0.292 | V31: 3 | W31: 0 | X31: 8 | Y31: 3 | Z31: 80000 | AA31: 1.84 | AB31: 80000 | AC31: 1.84 | AD31: 24395 | AE31: 889912 | AF31: 0.3049 | AG31: 103 | AH31: 5373534 | AI31: 15993 | AJ31: 577 | AK31: BELMONT AVE | AL31: JEROME ST | AM31: SUTTER AVE | AN31: BARBEY ST | AO31: BROOKLYN | AP31: 5 | AQ31: 8 | AR31: 19 | AS31: 60 | AT31: 42 | AU31: 31471 | AX31: YES
A32: 43466 | B32: BERRY | C32: NY005000520 | D32: 52 | E32: 52 | F32: 587 | G32: 587 | H32: NY005271B | I32: FEDERAL | J32: CONVENTIONAL | K32: NEW CONST | M32: 506 | N32: 506 | O32: 2129 | P32: 4.21 | R32: 944 | S32: 944 | T32: 220 | U32: 0.439 | V32: 8 | W32: 1 | X32: 17 | Y32: 6 | Z32: 604913 | AA32: 13.89 | AB32: 511178 | AC32: 11.74 | AD32: 77152 | AE32: 4520277 | AF32: 0.1275 | AG32: 68 | AH32: 5929376 | AI32: 2785 | AJ32: 511 | AK32: RICHMOND RD | AL32: DONGAN HILLS AVE | AM32: SEAVER AVE | AN32: JEFFERSON ST | AO32: STATEN ISLAND | AP32: 2 | AQ32: 11 | AR32: 24 | AS32: 63 | AT32: 50 | AU32: 18563 | AV32: 1980/10/01-ATP 7
A33: 43466 | B33: BERRY STREET-SOUTH 9TH STREET | C33: NY005011310 | D33: 357 | E33: 131 | F33: 777 | G33: 777 | H33: NY005288 | I33: FEDERAL | J33: TURNKEY | K33: NEW CONST | M33: 150 | N33: 150 | O33: 711 | P33: 4.74 | R33: 370 | S33: 370 | T33: 44 | U33: 0.299 | V33: 4 | W33: 0 | X33: 15 | Y33: 43530 | Z33: 129228 | AA33: 2.97 | AB33: 129228 | AC33: 2.97 | AD33: 39559 | AE33: 1341343 | AF33: 0.3061 | AG33: 125 | AH33: 17062418 | AI33: 23999 | AJ33: 627 | AK33: SOUTH 9TH ST | AL33: BEDFORD & DIVISION AVES | AM33: SOUTH 11TH ST | AN33: WYTHE AVE | AO33: BROOKLYN | AP33: 1 | AQ33: 7 | AR33: 18 | AS33: 50 | AT33: 33 | AU33: 34972 | AX33: YES
A34: 43466 | B34: BETHUNE GARDENS | C34: NY005010030 | D34: 160 | E34: 3 | F34: 271 | G34: 271 | H34: NY005070 | I34: FEDERAL | J34: CONVENTIONAL | K34: NEW CONST (ELD) | M34: 210 | N34: 210 | O34: 735 | P34: 3.5 | R34: 260 | S34: 260 | T34: 185 | U34: 0.885 | V34: 1 | W34: 0 | X34: 1 | Y34: 22 | Z34: 63546 | AA34: 1.46 | AB34: 63546 | AC34: 1.46 | AD34: 7751 | AE34: 1393115 | AF34: 0.122 | AG34: 178 | AH34: 3785397 | AI34: 5007 | AJ34: 337 | AK34: W 156TH ST | AL34: SAINT NICHOLAS AVE | AM34: AMSTERDAM AVE | AO34: MANHATTAN | AP34: 12 | AQ34: 13 | AR34: 30 | AS34: 71 | AT34: 7 | AU34: 24562 | AW34: EXCLUSIVELY
A35: 43466 | B35: BLAND | C35: NY005011860 | D35: 54 | E35: 186 | F35: 519 | G35: 519 | H35: NY005213K | I35: FEDERAL | J35: CONVENTIONAL | K35: NEW CONST | M35: 399 | N35: 400 | O35: 1850.5 | P35: 4.64 | R35: 863 | S35: 863 | T35: 167 | U35: 0.423 | V35: 5 | W35: 0 | X35: 5 | Y35: 10 | Z35: 269800 | AA35: 6.19 | AB35: 245785 | AC35: 5.64 | AD35: 43237 | AE35: 3668503 | AF35: 0.1603 | AG35: 139 | AH35: 5925000 | AI35: 3205 | AJ35: 585 | AK35: ROOSEVELT AVE | AL35: PRINCE ST | AM35: COLLEGE POINT BLVD | AN35: LIRR | AO35: QUEENS | AP35: 7 | AQ35: 6 | AR35: 11 | AS35: 40 | AT35: 20 | AU35: 19122 | AV35: 1977/07/01-ATP 1
A36: 43466 | B36: BORINQUEN PLAZA I | C36: NY005012430 | D36: 243 | E36: 243 | F36: 353 | G36: 353 | H36: NY005175 | I36: FEDERAL | J36: TURNKEY | K36: NEW CONST | M36: 509 | N36: 509 | O36: 2359.5 | P36: 4.64 | R36: 1123 | S36: 1123 | T36: 270 | U36: 0.539 | V36: 8 | W36: 2 | X36: 10 | Y36: 7 | Z36: 250875 | AA36: 5.76 | AB36: 250875 | AC36: 5.76 | AD36: 96902 | AE36: 4544080 | AF36: 0.3863 | AG36: 195 | AH36: 15625047 | AI36: 6556 | AJ36: 539 | AK36: MANHATTAN AVE | AL36: BOERUM ST | AM36: BUSHWICK AVE | AN36: VARET ST | AO36: BROOKLYN | AP36: 1 | AQ36: 7 | AR36: 18 | AS36: 53 | AT36: 34 | AU36: 27453 | AW36: PARTIALLY
A37: 43466 | B37: BORINQUEN PLAZA II | C37: NY005012430 | D37: 271 | E37: 243 | F37: 390 | G37: 353 | H37: NY005195 | I37: FEDERAL | J37: TURNKEY | K37: NEW CONST | M37: 425 | N37: 425 | O37: 2265.5 | P37: 5.33 | R37: 1123 | S37: 1123 | T37: 149 | U37: 0.351 | V37: 7 | W37: 0 | X37: 7 | Y37: 7 | Z37: 184000 | AA37: 4.22 | AB37: 184000 | AC37: 4.22 | AD37: 61115 | AE37: 4223000 | AF37: 0.3321 | AG37: 266 | AH37: 16411918 | AI37: 7244 | AJ37: 612 | AK37: BOERUM ST | AL37: HUMBOLDT ST | AM37: SEIGEL ST | AN37: BUSHWICK AVE | AO37: BROOKLYN | AP37: 1 | AQ37: 7 | AR37: 18 | AS37: 53 | AT37: 34 | AU37: 27759
A38: 43466 | B38: BOSTON ROAD PLAZA | C38: NY005010390 | D38: 189 | E38: 39 | F38: 304 | G38: 304 | H38: NY005095 | I38: FEDERAL | J38: CONVENTIONAL | K38: NEW CONST (ELD) | M38: 232 | N38: 235 | O38: 814 | P38: 3.51 | R38: 276 | S38: 276 | T38: 207 | U38: 0.892 | V38: 1 | W38: 1 | X38: 2 | Y38: 20 | Z38: 84416 | AA38: 1.94 | AB38: 84416 | AC38: 1.94 | AD38: 15045 | AE38: 1589318 | AF38: 0.1782 | AG38: 142 | AH38: 7125145 | AI38: 8452 | AJ38: 368 | AK38: MACE AVE | AL38: HOLLAND AVE | AM38: WARING AVE | AN38: BOSTON RD | AO38: BRONX | AP38: 11 | AQ38: 14 | AR38: 34 | AS38: 80 | AT38: 13 | AU38: 26542 | AW38: EXCLUSIVELY
A39: 43466 | B39: BOSTON SECOR | C39: NY005011380 | D39: 138 | E39: 138 | F39: 254 | G39: 254 | H39: NY005060 | I39: FEDERAL | J39: CONVENTIONAL | K39: NEW CONST | M39: 538 | N39: 538 | O39: 2487 | P39: 4.62 | R39: 1322 | S39: 1322 | T39: 184 | U39: 0.346 | V39: 4 | W39: 2 | X39: 5 | Y39: 13-14-17-18 | Z39: 612889 | AA39: 14.07 | AB39: 612889 | AC39: 14.07 | AD39: 36181 | AE39: 4849474 | AF39: 0.059 | AG39: 94 | AH39: 11894964 | AI39: 4778 | AJ39: 566 | AK39: IRT-DYRE AVE LINE | AL39: BOSTON RD | AM39: STEENWICK AVE | AO39: BRONX | AP39: 12 | AQ39: 16 | AR39: 36 | AS39: 83 | AT39: 12 | AU39: 25323
A40: 43466 | B40: BOULEVARD | C40: NY005020460 | D40: 46 | E40: 46 | F40: 637 | G40: 637 | H40: NY005369 | I40: MIXED FINANCE/LLC2 | J40: CONVENTIONAL | K40: NEW CONST | L40: 438 | M40: 1424 | N40: 1441 | O40: 5992 | P40: 4.21 | Q40: 846 | R40: 1850 | S40: 2696 | T40: 581 | U40: 0.416 | V40: 18 | W40: 0 | X40: 30 | Y40: 43630 | Z40: 1127650 | AA40: 25.89 | AB40: 1127650 | AC40: 25.89 | AD40: 170051 | AE40: 12141094 | AF40: 0.1508 | AG40: 104 | AH40: 13645438 | AI40: 2247 | AJ40: 518 | AK40: LINDEN BLVD | AL40: ASHFORD ST | AM40: WORTMAN AVE | AN40: SCHENCK AVE | AO40: BROOKLYN | AP40: 5 | AQ40: 8 | AR40: 19 | AS40: 60 | AT40: 42 | AU40: 18709
...

Sheet PNA (Totals)
A1: DEVELOPMENT | B1: DISCIPLINE | C1: PBS1 | D1: Sum of Year 1 | E1: Sum of Years 2-5 | F1: Sum of Years 6-10 | G1: Sum of Years 11-15 | H1: Sum of Years 16-20 | I1: Sum of Grand Total | J1: Five Year Need | K1: One Year Need
A2: 1010 EAST 178TH STREET | B2: Apartment Total | D2: 12487754 | F2: 6330800 | G2: 910472 | H2: 107100 | I2: 19836126 | J2: 12487754 | K2: 12487754
A3: 1010 EAST 178TH STREET | B3: Architectural Total | D3: 11628867 | E3: 13634 | F3: 280192 | I3: 11922692 | J3: 11642501 | K3: 11628867
A4: 1010 EAST 178TH STREET | B4: Conveying Total | E4: 1600000 | I4: 1600000 | J4: 1600000 | K4: 0
A5: 1010 EAST 178TH STREET | B5: Electrical Total | D5: 685057 | E5: 442912 | G5: 81216 | H5: 944171 | I5: 2153355 | J5: 1127969 | K5: 685057
A6: 1010 EAST 178TH STREET | B6: Mechanical Total | D6: 1380656 | E6: 71350 | F6: 4339000 | G6: 936203 | H6: 2003852 | I6: 8731060 | J6: 1452006 | K6: 1380656
A7: 1010 EAST 178TH STREET | B7: Site - Architectural Total | D7: 2216712 | F7: 132046 | I7: 2348758 | J7: 2216712 | K7: 2216712
A8: 1010 EAST 178TH STREET | B8: Site - Electrical Total | D8: 80124 | I8: 80124 | J8: 80124 | K8: 80124
A9: 1010 EAST 178TH STREET | B9: Site - Mechanical Total | G9: 75000 | H9: 192000 | I9: 267000 | J9: 0 | K9: 0
A10: 1010 EAST 178TH STREET | B10: Total | D10: 28479170 | E10: 2127896 | F10: 11082038 | G10: 2002890 | H10: 3247122 | I10: 46939117 | J10: 30607066 | K10: 28479170
A11: 104-14 TAPSCOTT STREET | B11: Apartment Total | D11: 1983376 | E11: 92560 | F11: 847889 | H11: 14400 | I11: 2938225 | J11: 2075936 | K11: 1983376
A12: 104-14 TAPSCOTT STREET | B12: Architectural Total | D12: 4667422 | F12: 135135 | I12: 4802557 | J12: 4667422 | K12: 4667422
A13: 104-14 TAPSCOTT STREET | B13: Electrical Total | D13: 321488 | E13: 0 | F13: 582568 | H13: 25000 | I13: 929057 | J13: 321488 | K13: 321488
A14: 104-14 TAPSCOTT STREET | B14: Mechanical Total | D14: 397471 | E14: 887 | F14: 6717 | H14: 467618 | I14: 872693 | J14: 398358 | K14: 397471
A15: 104-14 TAPSCOTT STREET | B15: Site - Architectural Total | D15: 153683 | I15: 153683 | J15: 153683 | K15: 153683
A16: 104-14 TAPSCOTT STREET | B16: Site - Mechanical Total | H16: 117000 | I16: 117000 | J16: 0 | K16: 0
A17: 104-14 TAPSCOTT STREET | B17: Total | D17: 7523440 | E17: 93447 | F17: 1572309 | H17: 624018 | I17: 9813214 | J17: 7616887 | K17: 7523440
A18: 1162-1176 WASHINGTON AVENUE | B18: Apartment Total | D18: 4639681 | F18: 1755600 | H18: 49500 | I18: 6444781 | J18: 4639681 | K18: 4639681
A19: 1162-1176 WASHINGTON AVENUE | B19: Architectural Total | D19: 9443592 | I19: 9443592 | J19: 9443592 | K19: 9443592
A20: 1162-1176 WASHINGTON AVENUE | B20: Conveying Total | D20: 800000 | I20: 800000 | J20: 800000 | K20: 800000
A21: 1162-1176 WASHINGTON AVENUE | B21: Electrical Total | D21: 866389 | E21: 8727 | F21: 76791 | H21: 108703 | I21: 1060610 | J21: 875116 | K21: 866389
A22: 1162-1176 WASHINGTON AVENUE | B22: Mechanical Total | D22: 64658 | E22: 4359708 | F22: 55757 | H22: 2072791 | I22: 6552914 | J22: 4424366 | K22: 64658
A23: 1162-1176 WASHINGTON AVENUE | B23: Site - Architectural Total | D23: 98268 | F23: 24759 | I23: 123027 | J23: 98268 | K23: 98268
A24: 1162-1176 WASHINGTON AVENUE | B24: Site - Mechanical Total | H24: 168000 | I24: 168000 | J24: 0 | K24: 0
A25: 1162-1176 WASHINGTON AVENUE | B25: Total | D25: 15912588 | E25: 4368435 | F25: 1912906 | H25: 2398994 | I25: 24592924 | J25: 20281023 | K25: 15912588
A26: 131 SAINT NICHOLAS AVENUE | B26: Apartment Total | D26: 5869224 | F26: 2660000 | H26: 41850 | I26: 8571074 | J26: 5869224 | K26: 5869224
A27: 131 SAINT NICHOLAS AVENUE | B27: Architectural Total | D27: 6627132 | F27: 765405 | I27: 7392538 | J27: 6627132 | K27: 6627132
A28: 131 SAINT NICHOLAS AVENUE | B28: Conveying Total | E28: 1600000 | I28: 1600000 | J28: 1600000 | K28: 0
A29: 131 SAINT NICHOLAS AVENUE | B29: Electrical Total | D29: 431247 | E29: 56114 | F29: 16596 | G29: 196585 | H29: 557700 | I29: 1258242 | J29: 487361 | K29: 431247
A30: 131 SAINT NICHOLAS AVENUE | B30: Mechanical Total | D30: 2290757 | E30: 7981 | F30: 1052707 | H30: 6933952 | I30: 10285398 | J30: 2298738 | K30: 2290757
A31: 131 SAINT NICHOLAS AVENUE | B31: Site - Architectural Total | D31: 16475 | E31: 663633 | F31: 287614 | H31: 24495 | I31: 992216 | J31: 680108 | K31: 16475
A32: 131 SAINT NICHOLAS AVENUE | B32: Site - Electrical Total | D32: 28279 | I32: 28279 | J32: 28279 | K32: 28279
A33: 131 SAINT NICHOLAS AVENUE | B33: Site - Mechanical Total | F33: 93000 | H33: 76800 | I33: 169800 | J33: 0 | K33: 0
A34: 131 SAINT NICHOLAS AVENUE | B34: Total | D34: 15263115 | E34: 2327728 | F34: 4875322 | G34: 196585 | H34: 7634797 | I34: 30297547 | J34: 17590843 | K34: 15263115
A35: 1471 WATSON AVENUE | B35: Apartment Total | D35: 6559328 | F35: 2553600 | H35: 53100 | I35: 9166028 | J35: 6559328 | K35: 6559328
A36: 1471 WATSON AVENUE | B36: Architectural Total | D36: 6440359 | F36: 67568 | I36: 6507927 | J36: 6440359 | K36: 6440359
A37: 1471 WATSON AVENUE | B37: Conveying Total | E37: 1600000 | I37: 1600000 | J37: 1600000 | K37: 0
A38: 1471 WATSON AVENUE | B38: Electrical Total | D38: 1503734 | F38: 12425 | H38: 32177 | I38: 1548335 | J38: 1503734 | K38: 1503734
A39: 1471 WATSON AVENUE | B39: Mechanical Total | D39: 543279 | E39: 2168991 | F39: 10518 | G39: 442670 | H39: 1087969 | I39: 4253427 | J39: 2712270 | K39: 543279
A40: 1471 WATSON AVENUE | B40: Site - Architectural Total | D40: 1002063 | F40: 61897 | I40: 1063960 | J40: 1002063 | K40: 1002063
...

Sheet PNA (Line Items) (TwinP Missing
A1: DEVELOPMENT | B1: DISCIPLINE | C1: PBS1 | D1: Sum of Year 1 | E1: Sum of Years 2-5 | F1: Sum of Years 6-10 | G1: Sum of Years 11-15 | H1: Sum of Years 16-20 | I1: Sum of Grand Total | J1: Five Year Need
A2: 1010 EAST 178TH STREET | B2: Apartment | C2: Architectural | D2: 10679744 | F2: 6330800 | I2: 17010544 | J2: 10679744
B3: Apartment | C3: Electrical | D3: 782077 | G3: 910472 | H3: 107100 | I3: 1799649 | J3: 782077
B4: Apartment | C4: Mechanical | D4: 1025934 | I4: 1025934 | J4: 1025934
B5: Apartment Total | D5: 12487754 | F5: 6330800 | G5: 910472 | H5: 107100 | I5: 19836126 | J5: 12487754
B6: Architectural | C6: Exterior | D6: 6410103 | E6: 9567 | I6: 6419670 | J6: 6419670
B7: Architectural | C7: Interior | D7: 5218764 | F7: 280192 | I7: 5498955 | J7: 5218764
B8: Architectural | C8: Structural | E8: 4067 | I8: 4067 | J8: 4067
B9: Architectural Total | D9: 11628867 | E9: 13634 | F9: 280192 | I9: 11922692 | J9: 11642501
B10: Conveying | C10: Traction Passenger Elevator | E10: 1600000 | I10: 1600000 | J10: 1600000
B11: Conveying Total | E11: 1600000 | I11: 1600000 | J11: 1600000
B12: Electrical | C12: Corridor Lighting | D12: 307520 | I12: 307520 | J12: 307520
B13: Electrical | C13: Emergency Lighting | D13: 6723 | I13: 6723 | J13: 6723
B14: Electrical | C14: Exit Lights | D14: 7695 | I14: 7695 | J14: 7695
B15: Electrical | C15: Lighting - Exterior Security / Riot Lights | D15: 147948 | I15: 147948 | J15: 147948
B16: Electrical | C16: Lighting Fixture - Fluorescent | D16: 0 | E16: 216511 | I16: 216511 | J16: 216511
B17: Electrical | C17: Lighting Fixture - HID | D17: 0 | G17: 6212 | I17: 6212 | J17: 0
B18: Electrical | C18: Lighting Fixture - Incandescent | D18: 33269 | I18: 33269 | J18: 33269
B19: Electrical | C19: Motor Starter / Contactor | D19: 8044 | H19: 64353 | I19: 72397 | J19: 8044
B20: Electrical | C20: Panelboard | D20: 102038 | E20: 210841 | G20: 75003 | H20: 375000 | I20: 762883 | J20: 312879
B21: Electrical | C21: Service Switch | H21: 326109 | I21: 326109 | J21: 0
B22: Electrical | C22: Stairhall Lighting | D22: 71819 | I22: 71819 | J22: 71819
B23: Electrical | C23: Switchboard | H23: 170929 | I23: 170929 | J23: 0
B24: Electrical | C24: Telephone | E24: 15560 | H24: 7780 | I24: 23340 | J24: 15560
B25: Electrical Total | D25: 685057 | E25: 442912 | G25: 81216 | H25: 944171 | I25: 2153355 | J25: 1127969
B26: Mechanical | C26: Air Compressor | D26: 11158 | E26: 0 | I26: 11158 | J26: 11158
B27: Mechanical | C27: Air Conditioning | D27: 13953 | E27: 43921 | H27: 43921 | I27: 101795 | J27: 57874
B28: Mechanical | C28: Climate Control | D28: 3161 | I28: 3161 | J28: 3161
B29: Mechanical | C29: Domestic Water System | D29: 1089061 | F29: 9000 | H29: 738900 | I29: 1836961 | J29: 1089061
B30: Mechanical | C30: Drainage / Sewage System | E30: 5259 | H30: 868840 | I30: 874099 | J30: 5259
B31: Mechanical | C31: Gas Service | H31: 240000 | I31: 240000 | J31: 0
B32: Mechanical | C32: Heating | D32: 887 | E32: 22170 | G32: 924166 | I32: 947223 | J32: 23057
B33: Mechanical | C33: Heating Plant | D33: 154132 | F33: 4330000 | G33: 12037 | H33: 41767 | I33: 4537935 | J33: 154132
B34: Mechanical | C34: Interior Compactor | D34: 49000 | I34: 49000 | J34: 49000
B35: Mechanical | C35: Non Residential Kitchen | D35: 12808 | I35: 12808 | J35: 12808
B36: Mechanical | C36: Non Residential Spaces | D36: 4076 | I36: 4076 | J36: 4076
B37: Mechanical | C37: Sprinkler System | D37: 0 | H37: 11624 | I37: 11624 | J37: 0
B38: Mechanical | C38: Standpipe System | D38: 33171 | H38: 58800 | I38: 91971 | J38: 33171
B39: Mechanical | C39: Ventilation | D39: 9249 | I39: 9249 | J39: 9249
B40: Mechanical Total | D40: 1380656 | E40: 71350 | F40: 4339000 | G40: 936203 | H40: 2003852 | I40: 8731060 | J40: 1452006
...

Sheet PNA (Line Items Updated) Correc
A1: DEVELOPMENT | B1: DISCIPLINE | C1: PBS1 | D1: Sum of Year 1 | E1: Sum of Years 2-5 | F1: Sum of Years 6-10 | G1: Sum of Years 11-15 | H1: Sum of Years 16-20 | I1: Sum of Grand Total | J1: Five Year Need | K1: One Year Need
A2: 1010 EAST 178TH STREET | B2: Apartment: Architectural | C2: Architectural | D2: 10679744 | F2: 6330800 | I2: 17010544 | J2: 10679744 | K2: 10679744
A3: 1010 EAST 178TH STREET | B3: Apartment: Electrical | C3: Electrical | D3: 782077 | G3: 910472 | H3: 107100 | I3: 1799649 | J3: 782077 | K3: 782077
A4: 1010 EAST 178TH STREET | B4: Apartment: Mechanical | C4: Mechanical | D4: 1025934 | I4: 1025934 | J4: 1025934 | K4: 1025934
A5: 1010 EAST 178TH STREET | B5: Apartment Total | D5: 12487754 | F5: 6330800 | G5: 910472 | H5: 107100 | I5: 19836126 | J5: 12487754 | K5: 12487754
A6: 1010 EAST 178TH STREET | B6: Architectural: Exterior | C6: Exterior | D6: 6410103 | E6: 9567 | I6: 6419670 | J6: 6419670 | K6: 6410103
A7: 1010 EAST 178TH STREET | B7: Architectural: Interior | C7: Interior | D7: 5218764 | F7: 280192 | I7: 5498955 | J7: 5218764 | K7: 5218764
A8: 1010 EAST 178TH STREET | B8: Architectural: Structural | C8: Structural | E8: 4067 | I8: 4067 | J8: 4067 | K8: 0
A9: 1010 EAST 178TH STREET | B9: Architectural Total | D9: 11628867 | E9: 13634 | F9: 280192 | I9: 11922692 | J9: 11642501 | K9: 11628867
A10: 1010 EAST 178TH STREET | B10: Conveying: Traction Passenger Elevator | C10: Traction Passenger Elevator | E10: 1600000 | I10: 1600000 | J10: 1600000 | K10: 0
A11: 1010 EAST 178TH STREET | B11: Conveying Total | E11: 1600000 | I11: 1600000 | J11: 1600000 | K11: 0
A12: 1010 EAST 178TH STREET | B12: Electrical: Corridor Lighting | C12: Corridor Lighting | D12: 307520 | I12: 307520 | J12: 307520 | K12: 307520
A13: 1010 EAST 178TH STREET | B13: Electrical: Emergency Lighting | C13: Emergency Lighting | D13: 6723 | I13: 6723 | J13: 6723 | K13: 6723
A14: 1010 EAST 178TH STREET | B14: Electrical: Exit Lights | C14: Exit Lights | D14: 7695 | I14: 7695 | J14: 7695 | K14: 7695
A15: 1010 EAST 178TH STREET | B15: Electrical: Lighting - Exterior Security / Riot Lights | C15: Lighting - Exterior Security / Riot Lights | D15: 147948 | I15: 147948 | J15: 147948 | K15: 147948
A16: 1010 EAST 178TH STREET | B16: Electrical: Lighting Fixture - Fluorescent | C16: Lighting Fixture - Fluorescent | D16: 0 | E16: 216511 | I16: 216511 | J16: 216511 | K16: 0
A17: 1010 EAST 178TH STREET | B17: Electrical: Lighting Fixture - HID | C17: Lighting Fixture - HID | D17: 0 | G17: 6212 | I17: 6212 | J17: 0 | K17: 0
A18: 1010 EAST 178TH STREET | B18: Electrical: Lighting Fixture - Incandescent | C18: Lighting Fixture - Incandescent | D18: 33269 | I18: 33269 | J18: 33269 | K18: 33269
A19: 1010 EAST 178TH STREET | B19: Electrical: Motor Starter / Contactor | C19: Motor Starter / Contactor | D19: 8044 | H19: 64353 | I19: 72397 | J19: 8044 | K19: 8044
A20: 1010 EAST 178TH STREET | B20: Electrical: Panelboard | C20: Panelboard | D20: 102038 | E20: 210841 | G20: 75003 | H20: 375000 | I20: 762883 | J20: 312879 | K20: 102038
A21: 1010 EAST 178TH STREET | B21: Electrical: Service Switch | C21: Service Switch | H21: 326109 | I21: 326109 | J21: 0 | K21: 0
A22: 1010 EAST 178TH STREET | B22: Electrical: Stairhall Lighting | C22: Stairhall Lighting | D22: 71819 | I22: 71819 | J22: 71819 | K22: 71819
A23: 1010 EAST 178TH STREET | B23: Electrical: Switchboard | C23: Switchboard | H23: 170929 | I23: 170929 | J23: 0 | K23: 0
A24: 1010 EAST 178TH STREET | B24: Electrical: Telephone | C24: Telephone | E24: 15560 | H24: 7780 | I24: 23340 | J24: 15560 | K24: 0
A25: 1010 EAST 178TH STREET | B25: Electrical Total | D25: 685057 | E25: 442912 | G25: 81216 | H25: 944171 | I25: 2153355 | J25: 1127969 | K25: 685057
A26: 1010 EAST 178TH STREET | B26: Mechanical: Air Compressor | C26: Air Compressor | D26: 11158 | E26: 0 | I26: 11158 | J26: 11158 | K26: 11158
A27: 1010 EAST 178TH STREET | B27: Mechanical: Air Conditioning | C27: Air Conditioning | D27: 13953 | E27: 43921 | H27: 43921 | I27: 101795 | J27: 57874 | K27: 13953
A28: 1010 EAST 178TH STREET | B28: Mechanical: Climate Control | C28: Climate Control | D28: 3161 | I28: 3161 | J28: 3161 | K28: 3161
A29: 1010 EAST 178TH STREET | B29: Mechanical: Domestic Water System | C29: Domestic Water System | D29: 1089061 | F29: 9000 | H29: 738900 | I29: 1836961 | J29: 1089061 | K29: 1089061
A30: 1010 EAST 178TH STREET | B30: Mechanical: Drainage / Sewage System | C30: Drainage / Sewage System | E30: 5259 | H30: 868840 | I30: 874099 | J30: 5259 | K30: 0
A31: 1010 EAST 178TH STREET | B31: Mechanical: Gas Service | C31: Gas Service | H31: 240000 | I31: 240000 | J31: 0 | K31: 0
A32: 1010 EAST 178TH STREET | B32: Mechanical: Heating | C32: Heating | D32: 887 | E32: 22170 | G32: 924166 | I32: 947223 | J32: 23057 | K32: 887
A33: 1010 EAST 178TH STREET | B33: Mechanical: Heating Plant | C33: Heating Plant | D33: 154132 | F33: 4330000 | G33: 12037 | H33: 41767 | I33: 4537935 | J33: 154132 | K33: 154132
A34: 1010 EAST 178TH STREET | B34: Mechanical: Interior Compactor | C34: Interior Compactor | D34: 49000 | I34: 49000 | J34: 49000 | K34: 49000
A35: 1010 EAST 178TH STREET | B35: Mechanical: Non Residential Kitchen | C35: Non Residential Kitchen | D35: 12808 | I35: 12808 | J35: 12808 | K35: 12808
A36: 1010 EAST 178TH STREET | B36: Mechanical: Non Residential Spaces | C36: Non Residential Spaces | D36: 4076 | I36: 4076 | J36: 4076 | K36: 4076
A37: 1010 EAST 178TH STREET | B37: Mechanical: Sprinkler System | C37: Sprinkler System | D37: 0 | H37: 11624 | I37: 11624 | J37: 0 | K37: 0
A38: 1010 EAST 178TH STREET | B38: Mechanical: Standpipe System | C38: Standpipe System | D38: 33171 | H38: 58800 | I38: 91971 | J38: 33171 | K38: 33171
A39: 1010 EAST 178TH STREET | B39: Mechanical: Ventilation | C39: Ventilation | D39: 9249 | I39: 9249 | J39: 9249 | K39: 9249
A40: 1010 EAST 178TH STREET | B40: Mechanical Total | D40: 1380656 | E40: 71350 | F40: 4339000 | G40: 936203 | H40: 2003852 | I40: 8731060 | J40: 1452006 | K40: 1380656
...

Sheet 1 5 20 Need
A1: DEVELOPMENT | B1: One Year Need | C1: Five Year Need | D1: Twenty Year Need | E1: Units | F1: 1 Year Per Unit | G1: 5 Year Per Unit | H1: 20 Year Per Unit | I1: DEVELOPMENT | J1: DevProper | K1: HUD AMP# | L1: TDS# | M1: CONSOLIDATED TDS# | N1: DEVELOPMENT EDP# | O1: OPERATING EDP# | P1: HUD # | Q1: PROGRAM | R1: METHOD | S1: TYPE | T1: NUMBER OF SECTION 8 TRANSITION APARTMENTS | U1: NUMBER OF CURRENT APARTMENTS | V1: TOTAL NUMBER OF APARTMENTS | W1: NUMBER OF RENTAL ROOMS | X1: AVG NO R/R PER APARTMENT | Y1: POPULATION SECTION 8 TRANSITION | Z1: POPULATION PUBLIC HOUSING | AA1: TOTAL POPULATION | AB1: TOTAL # OF FIXED INCOME HOUSEHOLD | AC1: PERCENT FIXED INCOME HOUSEHOLDS | AD1: NUMBER OF RESIDENTIAL BLDGS | AE1: NUMBER OF NON-RESIDENTIAL BLDGS | AF1: NUMBER OF STAIRHALLS | AG1: NUMBER OF STORIES | AH1: TOTAL AREA SQ FT | AI1: ACRES | AJ1: NET DEV AREA SQ FT | AK1: EXCLUDING PARK ACRES | AL1: BLDG COVERAGE SQ FT | AM1: CUBAGE CU FT | AN1: BLDG COVERAGE % | AO1: DENSITY | AP1: DEVELOPMENT COST | AQ1: PER RENTAL ROOM | AR1: AVG MONTHLY GROSS RENT | AS1: LOCATION STREET A | AT1: LOCATION STREET B | AU1: LOCATION STREET C | AV1: LOCATION STREET D | AW1: BOROUGH | AX1: Borough2 | AY1: COMMUNITY DISTIRCT | AZ1: US CONGRESSIONAL DISTRICT | BA1: Congresssional Rep(s) | BB1: NY STATE SENATE DISTRICT | BC1: State Senator(s) | BD1: NY STATE ASSEMBLY DISTRICT | BE1: Assembly Member(s) | BF1: NY CITY COUNCIL DISTRICT | BG1: COMPLETION DATE | BH1: FEDERALIZED DEVELOPMENT | BI1: SENIOR DEVELOPMENT | BJ1: ELECTRICITY PAID BY RESIDENTS | BK1: PRIVATE MANAGEMENT | BL1: 5 Year Per Unit RANK | BM1: Council Member | BN1: Apartments 5 Year Cost | BO1: Buildings 5 Year Cost | BP1: Systems 5 Year Cost | BQ1: Site + Grounds 5 Year Cost | BR1: Average Household Size | BS1: Five Year Need | BT1: Diff | BU1: NYCHA Average Apartments 5 Year Cost | BV1: NYCHA Average Buildings 5 Year Cost | BW1: NYCHA Average Systems 5 Year Cost | BX1: NYCHA Average Site + Grounds 5 Year Cost | BY1: NYCHA Average Five Year Need | BZ1: Apartments 5 Year Cost % of Total Development Need | CA1: Buildings 5 Year Cost % of Total Development Need | CB1: Systems 5 Year Cost % of Total Development Need | CC1: Site + Grounds 5 Year Cost % of Total Development Need | CD1: Total % of Needs | CE1: Category | CF1: Test Apartment | CG1: Test Building | CH1: Test Site + Grounds | CI1: Test Systems | CJ1: Apt 5 Year Cost % of Total Development Need | CK1: Bld 5 Year Cost % of Total Development Need | CL1: Sys 5 Year Cost % of Total Development Need | CM1: S + Grounds 5 Year Cost % of Total Development Need | CN1: Apartment Cost Per Unit | CO1: Building Cost Per Unit | CP1: Site + Grounds Cost Per Unit | CQ1: Systems Cost Per Unit | CR1: Apartments Per Unit Cost % of Total Development Per Unit Cost | CS1: Buildings Per Unit Cost % of Total Development Per Unit Cost | CT1: Systems Per Unit Cost % of Total Development Per Unit Cost | CU1: Site + Grounds Per Unit Cost % of Total Development Per Unit Cost | CV1: Average NYCHA Units | CW1: NYCHA Average Apartment Cost Per Unit | CX1: NYCHA Average Building Cost Per Unit | CY1: NYCHA Average Site + Grounds Cost Per Unit | CZ1: NYCHA Average Systems Cost Per Unit | DA1: Apartments Per Unit Cost % of Average NYCHA Development Per Unit Cost | DB1: Buildings Per Unit Cost % of Average NYCHA Development Per Unit Cost | DC1: Systems Per Unit Cost % of Average NYCHA Development Per Unit Cost | DD1: Site + Grounds Per Unit Cost % of Average NYCHA Development Per Unit Cost | DE1: NYCHA AVERAGE PER UNIT NEED
A2: 1010 EAST 178TH STREET | B2: 28479170 | C2: 30607066 | D2: 46939117 | E2: 220 | F2: =B2/E2 -> 129450.77 | G2: =C2/E2 -> 139123.03 | H2: =D2/E2 -> 213359.62 | I2: 1010 EAST 178TH STREET | J2: 1010 East 178th Street | K2: NY005011330 | L2: 180 | M2: 180 | N2: 289 | O2: 289 | P2: NY005090 | Q2: FEDERAL | R2: CONVENTIONAL | S2: NEW CONST | U2: 218 | V2: 220 | W2: 918 | X2: 4.21 | Z2: 450 | AA2: 450 | AB2: 89 | AC2: 0.418 | AD2: 1 | AE2: 0 | AF2: 1 | AG2: 21 | AH2: 88172 | AI2: 2.02 | AJ2: 88172 | AK2: 2.02 | AL2: 14961 | AM2: 1841787 | AN2: 0.1697 | AO2: 223 | AP2: 5031405 | AQ2: 5341 | AR2: 503 | AS2: E TREMONT AVE | AT2: BRYANT AVE | AU2: E 178TH ST | AV2: BOSTON RD | AW2: BRONX | AX2: =PROPER(AW2) -> Bronx | AY2: 6 | AZ2: 15 | BA2: José Serrano | BB2: 32 | BC2: Luis R. Sepúlveda | BD2: 87 | BE2: Karines Reyes | BF2: 15 | BG2: 26023 | BL2: 267 | BM2: Ritchie Torres | BN2: 12487754 | BO2: 11642501 | BP2: 4179975 | BQ2: 2296836 | BR2: =AA2/E2 -> 2.0454545 | BS2: 30607066 | BT2: =SUM(BN2:BQ2)-BS2 -> 0 | BZ2: =BN2/BS2 -> 0.40800232 | CA2: =BO2/BS2 -> 0.38038605 | CB2: =BP2/BS2 -> 0.13656895 | CC2: =BQ2/BS2 -> 0.075042672 | CD2: =SUM(BZ2:CC2) -> 1 | CE2: Development | CF2: 12487754 | CG2: 11642501 | CH2: 4179975 | CI2: 2296836 | CN2: =CF2/E2 -> 56762.518 | CO2: =CG2/E2 -> 52920.459 | CP2: =CH2/E2 -> 18999.886 | CQ2: =CI2/E2 -> 10440.164 | CR2: =CN2/G2 -> 0.40800232 | CS2: =CO2/G2 -> 0.38038605 | CT2: =CP2/G2 -> 0.13656895 | CU2: =CQ2/G2 -> 0.075042672
A3: 104-14 TAPSCOTT STREET | B3: 7523440 | C3: 7616887 | D3: 9813214 | E3: 30 | F3: =B3/E3 -> 250781.33 | G3: =C3/E3 -> 253896.23 | H3: =D3/E3 -> 327107.13 | I3: 104-14 TAPSCOTT STREET | J3: 104-14 Tapscott Street | K3: NY005011670 | L3: 242 | M3: 167 | N3: 361 | O3: 283 | P3: NY005174 | Q3: FEDERAL | R3: TURNKEY | S3: NEW CONST | U3: 30 | V3: 30 | W3: 131 | X3: 4.37 | Z3: 65 | AA3: 65 | AB3: 5 | AC3: 0.172 | AD3: 1 | AE3: 0 | AF3: 1 | AG3: 4 | AH3: 10000 | AI3: 0.23 | AJ3: 10000 | AK3: 0.23 | AL3: 6983 | AM3: 351238 | AN3: 0.6983 | AO3: 283 | AP3: 839110 | AQ3: 6505 | AR3: 643 | AS3: TAPSCOTT ST | AT3: UNION ST | AU3: SUTTER AVE | AV3: BLAKE AVE | AW3: BROOKLYN | AX3: =PROPER(AW3) -> Brooklyn | AY3: 16 | AZ3: 9 | BA3: Yvette Clarke | BB3: 20 | BC3: Zellnor Myrie | BD3: 55 | BE3: Latrice Walker | BF3: 41 | BG3: 26603 | BL3: 28 | BM3: Alicka Ampry-Samuel | BN3: 2075936 | BO3: 4667422 | BP3: 719846 | BQ3: 153683 | BR3: =AA3/E3 -> 2.1666667 | BS3: 7616887 | BT3: =SUM(BN3:BQ3)-BS3 -> 0 | BZ3: =BN3/BS3 -> 0.27254389 | CA3: =BO3/BS3 -> 0.61277291 | CB3: =BP3/BS3 -> 0.094506588 | CC3: =BQ3/BS3 -> 0.020176615 | CD3: =SUM(BZ3:CC3) -> 1 | CE3: Development | CF3: 2075936 | CG3: 4667422 | CH3: 719846 | CI3: 153683 | CN3: =CF3/E3 -> 69197.867 | CO3: =CG3/E3 -> 155580.73 | CP3: =CH3/E3 -> 23994.867 | CQ3: =CI3/E3 -> 5122.7667 | CR3: =CN3/G3 -> 0.27254389 | CS3: =CO3/G3 -> 0.61277291 | CT3: =CP3/G3 -> 0.094506588 | CU3: =CQ3/G3 -> 0.020176615
A4: 1162-1176 WASHINGTON AVENUE | B4: 15912588 | C4: 20281023 | D4: 24592924 | E4: 66 | F4: =B4/E4 -> 241099.82 | G4: =C4/E4 -> 307288.23 | H4: =D4/E4 -> 372620.06 | I4: 1162-1176 WASHINGTON AVENUE | J4: 1162-1176 Washington Avenue | K4: NY005013080 | L4: 233 | M4: 308 | N4: 354 | O4: 344 | P4: NY005138 | Q4: FEDERAL | R4: TURNKEY | S4: REHAB | U4: 65 | V4: 66 | W4: 293.5 | X4: 4.52 | Z4: 170 | AA4: 170 | AB4: 21 | AC4: 0.328 | AD4: 1 | AE4: 0 | AF4: 1 | AG4: 6 | AH4: 18987 | AI4: 0.44 | AJ4: 18987 | AK4: 0.44 | AL4: 12231 | AM4: 851926 | AN4: 0.6442 | AO4: 386 | AP4: 2205187 | AQ4: 7302 | AR4: 440 | AS4: E 167TH ST | AT4: E 168TH ST | AU4: THIRD AVE | AV4: WASHINGTON AVE | AW4: BRONX | AX4: =PROPER(AW4) -> Bronx | AY4: 3 | AZ4: 15 | BA4: José Serrano | BB4: 32 | BC4: Luis R. Sepúlveda | BD4: 79 | BE4: Michael Blake | BF4: 16 | BG4: 27759 | BL4: 9 | BM4: Vanessa L Gibson | BN4: 4639681 | BO4: 9443592 | BP4: 6099482 | BQ4: 98268 | BR4: =AA4/E4 -> 2.5757576 | BS4: 20281023 | BT4: =SUM(BN4:BQ4)-BS4 -> 0 | BZ4: =BN4/BS4 -> 0.22876957 | CA4: =BO4/BS4 -> 0.46563687 | CB4: =BP4/BS4 -> 0.30074824 | CC4: =BQ4/BS4 -> 0.0048453177 | CD4: =SUM(BZ4:CC4) -> 1 | CE4: Development | CF4: 4639681 | CG4: 9443592 | CH4: 6099482 | CI4: 98268 | CN4: =CF4/E4 -> 70298.197 | CO4: =CG4/E4 -> 143084.73 | CP4: =CH4/E4 -> 92416.394 | CQ4: =CI4/E4 -> 1488.9091 | CR4: =CN4/G4 -> 0.22876957 | CS4: =CO4/G4 -> 0.46563687 | CT4: =CP4/G4 -> 0.30074824 | CU4: =CQ4/G4 -> 0.0048453177
A5: 131 SAINT NICHOLAS AVENUE | B5: 15263115 | C5: 17590843 | D5: 30297547 | E5: 100 | F5: =B5/E5 -> 152631.15 | G5: =C5/E5 -> 175908.43 | H5: =D5/E5 -> 302975.47 | I5: 131 SAINT NICHOLAS AVENUE | J5: 131 Saint Nicholas Avenue | K5: NY005010970 | L5: 154 | M5: 97 | N5: 264 | O5: 261 | P5: NY005065 | Q5: FEDERAL | R5: CONVENTIONAL | S5: NEW CONST | U5: 98 | V5: 100 | W5: 386 | X5: 3.94 | Z5: 165 | AA5: 165 | AB5: 41 | AC5: 0.427 | AD5: 1 | AE5: 0 | AF5: 1 | AG5: 17 | AH5: 29359 | AI5: 0.67 | AJ5: 29359 | AK5: 0.67 | AL5: 5759 | AM5: 771591 | AN5: 0.1962 | AO5: 246 | AP5: 1880013 | AQ5: 4694 | AR5: 529 | AS5: SAINT NICHOLAS AVE | AT5: W 116TH ST | AU5: W 117TH ST | AW5: MANHATTAN | AX5: =PROPER(AW5) -> Manhattan | AY5: 10 | AZ5: 13 | BA5: Adriano Espaillat | BB5: 30 | BC5: Brian A. Benjamin | BD5: 70 | BE5: Inez E. Dickens | BF5: 9 | BG5: 23832 | BL5: 165 | BM5: Bill Perkins | BN5: 5869224 | BO5: 6627132 | BP5: 4386099 | BQ5: 708387 | BR5: =AA5/E5 -> 1.65 | BS5: 17590843 | BT5: =SUM(BN5:BQ5)-BS5 -> -1 | BZ5: =BN5/BS5 -> 0.33365223 | CA5: =BO5/BS5 -> 0.3767376 | CB5: =BP5/BS5 -> 0.2493399 | CC5: =BQ5/BS5 -> 0.040270213 | CD5: =SUM(BZ5:CC5) -> 0.99999994 | CE5: Development | CF5: 5869224 | CG5: 6627132 | CH5: 4386099 | CI5: 708387 | CN5: =CF5/E5 -> 58692.24 | CO5: =CG5/E5 -> 66271.32 | CP5: =CH5/E5 -> 43860.99 | CQ5: =CI5/E5 -> 7083.87 | CR5: =CN5/G5 -> 0.33365223 | CS5: =CO5/G5 -> 0.3767376 | CT5: =CP5/G5 -> 0.2493399 | CU5: =CQ5/G5 -> 0.040270213
A6: 1471 WATSON AVENUE | B6: 16062903 | C6: 19831894 | D6: 24501816 | E6: 96 | F6: =B6/E6 -> 167321.91 | G6: =C6/E6 -> 206582.23 | H6: =D6/E6 -> 255227.25 | I6: 1471 WATSON AVENUE | J6: 1471 Watson Avenue | K6: NY005010670 | L6: 214 | M6: 67 | N6: 332 | O6: 222 | P6: NY005162 | Q6: FEDERAL | R6: TURNKEY | S6: NEW CONST | U6: 96 | V6: 96 | W6: 386 | X6: 4.02 | Z6: 156 | AA6: 156 | AB6: 47 | AC6: 0.505 | AD6: 1 | AE6: 0 | AF6: 1 | AG6: 6 | AH6: 39937 | AI6: 0.92 | AJ6: 39937 | AK6: 0.92 | AL6: 13337 | AM6: 810629 | AN6: 0.334 | AO6: 170 | AP6: 2278928 | AQ6: 5814 | AR6: 452 | AS6: WATSON AVE | AT6: COLGATE AVE | AU6: EVERGREEN AVE | AW6: BRONX | AX6: =PROPER(AW6) -> Bronx | AY6: 9 | AZ6: 15 | BA6: José Serrano | BB6: 32 | BC6: Luis R. Sepúlveda | BD6: 85 | BE6: Kenny Burgos | BF6: 17 | BG6: 25933 | BL6: 69 | BM6: Rafael Salamanca | BN6: 6559328 | BO6: 6440359 | BP6: 5816004 | BQ6: 1016203 | BR6: =AA6/E6 -> 1.625 | BS6: 19831894 | BT6: =SUM(BN6:BQ6)-BS6 -> 0 | BZ6: =BN6/BS6 -> 0.33074642 | CA6: =BO6/BS6 -> 0.32474755 | CB6: =BP6/BS6 -> 0.29326518 | CC6: =BQ6/BS6 -> 0.051240845 | CD6: =SUM(BZ6:CC6) -> 1 | CE6: Development | CF6: 6559328 | CG6: 6440359 | CH6: 5816004 | CI6: 1016203 | CN6: =CF6/E6 -> 68326.333 | CO6: =CG6/E6 -> 67087.073 | CP6: =CH6/E6 -> 60583.375 | CQ6: =CI6/E6 -> 10585.448 | CR6: =CN6/G6 -> 0.33074642 | CS6: =CO6/G6 -> 0.32474755 | CT6: =CP6/G6 -> 0.29326518 | CU6: =CQ6/G6 -> 0.051240845
A7: 154 WEST 84TH STREET | B7: 4430342 | C7: 5186588 | D7: 10438024 | E7: 35 | F7: =B7/E7 -> 126581.2 | G7: =C7/E7 -> 148188.23 | H7: =D7/E7 -> 298229.26 | I7: 154 WEST 84TH STREET | J7: 154 West 84th Street | K7: NY005013590 | L7: 359 | M7: 359 | N7: 840 | O7: 840 | P7: NY005270 | Q7: FEDERAL | R7: TURNKEY | S7: NEW CONST | U7: 35 | V7: 35 | W7: 157.5 | X7: 4.5 | Z7: 74 | AA7: 74 | AB7: 7 | AC7: 0.2 | AD7: 1 | AE7: 0 | AF7: 1 | AG7: 7 | AH7: 9621 | AI7: 0.22 | AJ7: 9621 | AK7: 0.22 | AL7: 5774 | AM7: 361857 | AN7: 0.6001 | AO7: 336 | AP7: 4503296 | AQ7: 28412 | AR7: 644 | AS7: AMSTERDAM AVE | AT7: W 84TH ST | AU7: COLUMBUS AVE | AW7: MANHATTAN | AX7: =PROPER(AW7) -> Manhattan | AY7: 7 | AZ7: 10 | BA7: Jerrold Nadler | BB7: 29 | BC7: José M. Serrano | BD7: 69 | BE7: Daniel J. O'Donnell | BF7: 6 | BG7: 35155 | BJ7: YES | BK7: YES | BL7: 246 | BM7: Helen Rosenthal | BN7: 1751964 | BO7: 2122420 | BP7: 1197472 | BQ7: 114732 | BR7: =AA7/E7 -> 2.1142857 | BS7: 5186588 | BT7: =SUM(BN7:BQ7)-BS7 -> 0 | BZ7: =BN7/BS7 -> 0.33778739 | CA7: =BO7/BS7 -> 0.40921315 | CB7: =BP7/BS7 -> 0.23087857 | CC7: =BQ7/BS7 -> 0.022120901 | CD7: =SUM(BZ7:CC7) -> 1 | CE7: Development | CF7: 1751964 | CG7: 2122420 | CH7: 1197472 | CI7: 114732 | CN7: =CF7/E7 -> 50056.114 | CO7: =CG7/E7 -> 60640.571 | CP7: =CH7/E7 -> 34213.486 | CQ7: =CI7/E7 -> 3278.0571 | CR7: =CN7/G7 -> 0.33778739 | CS7: =CO7/G7 -> 0.40921315 | CT7: =CP7/G7 -> 0.23087857 | CU7: =CQ7/G7 -> 0.022120901
A8: 303 VERNON AVENUE | B8: 37414870 | C8: 43867730 | D8: 51404716 | E8: 234 | F8: =B8/E8 -> 159892.61 | G8: =C8/E8 -> 187468.93 | H8: =D8/E8 -> 219678.27 | I8: 303 VERNON AVENUE | J8: 303 Vernon Avenue | K8: NY005010730 | L8: 156 | M8: 73 | N8: 267 | O8: 267 | P8: NY005068 | Q8: FEDERAL | R8: CONVENTIONAL | S8: NEW CONST | U8: 234 | V8: 234 | W8: 1101 | X8: 4.71 | Z8: 541 | AA8: 541 | AB8: 100 | AC8: 0.431 | AD8: 1 | AE8: 0 | AF8: 1 | AG8: 24 | AH8: 110000 | AI8: 2.53 | AJ8: 110000 | AK8: 2.53 | AL8: 11311 | AM8: 2207369 | AN8: 0.1028 | AO8: 214 | AP8: 4703702 | AQ8: 4272 | AR8: 511 | AS8: VERNON AVE | AT8: MARCUS GARVEY BLVD | AU8: MYRTLE AVE | AW8: BROOKLYN | AX8: =PROPER(AW8) -> Brooklyn | AY8: 3 | AZ8: 8 | BA8: Hakeem Jeffries | BB8: 18 | BC8: Julia Salazar | BD8: 54 | BE8: Erik M. Dilan | BF8: 36 | BG8: 24623 | BL8: 125 | BM8: Robert Cornegy | BN8: 22423740 | BO8: 11498624 | BP8: 8704028 | BQ8: 1241337 | BR8: =AA8/E8 -> 2.3119658 | BS8: 43867730 | BT8: =SUM(BN8:BQ8)-BS8 -> -1 | BZ8: =BN8/BS8 -> 0.51116709 | CA8: =BO8/BS8 -> 0.26212033 | CB8: =BP8/BS8 -> 0.19841528 | CC8: =BQ8/BS8 -> 0.02829727 | CD8: =SUM(BZ8:CC8) -> 0.99999998 | CE8: Development | CF8: 22423740 | CG8: 11498624 | CH8: 8704028 | CI8: 1241337 | CN8: =CF8/E8 -> 95827.949 | CO8: =CG8/E8 -> 49139.419 | CP8: =CH8/E8 -> 37196.701 | CQ8: =CI8/E8 -> 5304.859 | CR8: =CN8/G8 -> 0.51116709 | CS8: =CO8/G8 -> 0.26212033 | CT8: =CP8/G8 -> 0.19841528 | CU8: =CQ8/G8 -> 0.02829727
A9: 335 EAST 111TH STREET | B9: 13270397 | C9: 14400934 | D9: 18924521 | E9: 66 | F9: =B9/E9 -> 201066.62 | G9: =C9/E9 -> 218195.97 | H9: =D9/E9 -> 286735.17 | I9: 335 EAST 111TH STREET | J9: 335 East 111th Street | K9: NY005010640 | L9: 203 | M9: 64 | N9: 320 | O9: 219 | P9: NY005126 | Q9: FEDERAL | R9: TURNKEY | S9: NEW CONST | U9: 66 | V9: 66 | W9: 259 | X9: 3.92 | Z9: 114 | AA9: 114 | AB9: 33 | AC9: 0.5 | AD9: 1 | AE9: 0 | AF9: 1 | AG9: 6 | AH9: 20205 | AI9: 0.46 | AJ9: 20205 | AK9: 0.46 | AL9: 9143 | AM9: 530550 | AN9: 0.4525 | AO9: 248 | AP9: 1241825 | AQ9: 4651 | AR9: 482 | AS9: SECOND AVE | AT9: E 111TH ST | AU9: FIRST AVE | AV9: E 112TH ST | AW9: MANHATTAN | AX9: =PROPER(AW9) -> Manhattan | AY9: 11 | AZ9: 13 | BA9: Adriano Espaillat | BB9: 29 | BC9: José M. Serrano | BD9: 68 | BE9: Robert J. Rodriguez | BF9: 8 | BG9: 25384 | BL9: 54 | BM9: Diana Ayala | BN9: 4449621 | BO9: 5162298 | BP9: 4287355 | BQ9: 501659 | BR9: =AA9/E9 -> 1.7272727 | BS9: 14400934 | BT9: =SUM(BN9:BQ9)-BS9 -> -1 | BZ9: =BN9/BS9 -> 0.30898142 | CA9: =BO9/BS9 -> 0.35846967 | CB9: =BP9/BS9 -> 0.29771368 | CC9: =BQ9/BS9 -> 0.034835171 | CD9: =SUM(BZ9:CC9) -> 0.99999993 | CE9: Development | CF9: 4449621 | CG9: 5162298 | CH9: 4287355 | CI9: 501659 | CN9: =CF9/E9 -> 67418.5 | CO9: =CG9/E9 -> 78216.636 | CP9: =CH9/E9 -> 64959.924 | CQ9: =CI9/E9 -> 7600.8939 | CR9: =CN9/G9 -> 0.30898142 | CS9: =CO9/G9 -> 0.35846967 | CT9: =CP9/G9 -> 0.29771368 | CU9: =CQ9/G9 -> 0.034835171
A10: 344 EAST 28TH STREET | B10: 16984472 | C10: 29487580 | D10: 46600585 | E10: 225 | F10: =B10/E10 -> 75486.542 | G10: =C10/E10 -> 131055.91 | H10: =D10/E10 -> 207113.71 | I10: 344 EAST 28TH STREET | J10: 344 East 28th Street | K10: NY005021850 | L10: 185 | M10: 153 | N10: 452 | O10: 452 | P10: NY005374 | Q10: MIXED FINANCE/LLC2 | R10: CONVENTIONAL | S10: NEW CONST | T10: 73 | U10: 225 | V10: 225 | W10: 985.5 | X10: 4.38 | Y10: 146 | Z10: 281 | AA10: 427 | AB10: 111 | AC10: 0.502 | AD10: 1 | AE10: 0 | AF10: 1 | AG10: 26 | AH10: 44644 | AI10: 1.02 | AJ10: 44644 | AK10: 1.02 | AL10: 7889 | AM10: 1946457 | AN10: 0.1767 | AO10: 419 | AP10: 4980000 | AQ10: 5053 | AR10: 516 | AS10: E 27TH ST | AT10: NEW ST | AU10: E 28TH ST | AV10: FIRST AVE | AW10: MANHATTAN | AX10: =PROPER(AW10) -> Manhattan | AY10: 6 | AZ10: 12 | BA10: Carolyn Maloney | BB10: 27 | BC10: Brad Hoylman | BD10: 74 | BE10: Harvey Epstein | BF10: 2 | BG10: 26023 | BL10: 286 | BM10: Carlina Rivera | BN10: 15371675 | BO10: 11031713 | BP10: 2004411 | BQ10: 1079781 | BR10: =AA10/E10 -> 1.8977778 | BS10: 29487580 | BT10: =SUM(BN10:BQ10)-BS10 -> 0 | BZ10: =BN10/BS10 -> 0.5212932 | CA10: =BO10/BS10 -> 0.37411388 | CB10: =BP10/BS10 -> 0.067974754 | CC10: =BQ10/BS10 -> 0.036618163 | CD10: =SUM(BZ10:CC10) -> 1 | CE10: Development | CF10: 15371675 | CG10: 11031713 | CH10: 2004411 | CI10: 1079781 | CN10: =CF10/E10 -> 68318.556 | CO10: =CG10/E10 -> 49029.836 | CP10: =CH10/E10 -> 8908.4933 | CQ10: =CI10/E10 -> 4799.0267 | CR10: =CN10/G10 -> 0.5212932 | CS10: =CO10/G10 -> 0.37411388 | CT10: =CP10/G10 -> 0.067974754 | CU10: =CQ10/G10 -> 0.036618163
A11: 45 ALLEN STREET | B11: 22918730 | C11: 23214849 | D11: 32907908 | E11: 107 | F11: =B11/E11 -> 214193.74 | G11: =C11/E11 -> 216961.21 | H11: =D11/E11 -> 307550.54 | I11: 45 ALLEN STREET | J11: 45 Allen Street | K11: NY005011000 | L11: 265 | M11: 100 | N11: 380 | O11: 312 | P11: NY005186 | Q11: FEDERAL | R11: TURNKEY | S11: NEW CONST | U11: 107 | V11: 107 | W11: 537.5 | X11: 5.02 | Z11: 237 | AA11: 237 | AB11: 46 | AC11: 0.442 | AD11: 1 | AE11: 1 | AF11: 2 | AG11: 14 | AH11: 39609 | AI11: 0.91 | AJ11: 39609 | AK11: 0.91 | AL11: 8031 | AM11: 950162 | AN11: 0.2028 | AO11: 260 | AP11: 4290021 | AQ11: 7981 | AR11: 687 | AS11: GRAND ST | AT11: ALLEN ST | AU11: HESTER ST | AV11: ELDRIDGE ST | AW11: MANHATTAN | AX11: =PROPER(AW11) -> Manhattan | AY11: 3 | AZ11: 7 | BA11: Nydia Velázquez | BB11: 26 | BC11: Brian Kavanagh | BD11: 65 | BE11: Yuh-Line Niou | BF11: 1 | BG11: 27241 | BL11: 57 | BM11: Margaret Chin | BN11: 10949957 | BO11: 8788075 | BP11: 2257345 | BQ11: 1219471 | BR11: =AA11/E11 -> 2.2149533 | BS11: 23214849 | BT11: =SUM(BN11:BQ11)-BS11 -> -1 | BZ11: =BN11/BS11 -> 0.47167901 | CA11: =BO11/BS11 -> 0.37855405 | CB11: =BP11/BS11 -> 0.097237118 | CC11: =BQ11/BS11 -> 0.052529784 | CD11: =SUM(BZ11:CC11) -> 0.99999996 | CE11: Development | CF11: 10949957 | CG11: 8788075 | CH11: 2257345 | CI11: 1219471 | CN11: =CF11/E11 -> 102336.05 | CO11: =CG11/E11 -> 82131.542 | CP11: =CH11/E11 -> 21096.682 | CQ11: =CI11/E11 -> 11396.925 | CR11: =CN11/G11 -> 0.47167901 | CS11: =CO11/G11 -> 0.37855405 | CT11: =CP11/G11 -> 0.097237118 | CU11: =CQ11/G11 -> 0.052529784
